Traceback (most recent call last):
  File "/Users/graceliu/opt/anaconda3/lib/python3.8/site-packages/jupyter_cache/executors/utils.py", line 58, in single_nb_execution
    executenb(
  File "/Users/graceliu/opt/anaconda3/lib/python3.8/site-packages/nbclient/client.py", line 1087, in execute
    return NotebookClient(nb=nb, resources=resources, km=km, **kwargs).execute()
  File "/Users/graceliu/opt/anaconda3/lib/python3.8/site-packages/nbclient/util.py", line 74, in wrapped
    return just_run(coro(*args, **kwargs))
  File "/Users/graceliu/opt/anaconda3/lib/python3.8/site-packages/nbclient/util.py", line 53, in just_run
    return loop.run_until_complete(coro)
  File "/Users/graceliu/opt/anaconda3/lib/python3.8/asyncio/base_events.py", line 616, in run_until_complete
    return future.result()
  File "/Users/graceliu/opt/anaconda3/lib/python3.8/site-packages/nbclient/client.py", line 540, in async_execute
    await self.async_execute_cell(
  File "/Users/graceliu/opt/anaconda3/lib/python3.8/site-packages/nbclient/client.py", line 832, in async_execute_cell
    self._check_raise_for_error(cell, exec_reply)
  File "/Users/graceliu/opt/anaconda3/lib/python3.8/site-packages/nbclient/client.py", line 740, in _check_raise_for_error
    raise CellExecutionError.from_cell_and_msg(cell, exec_reply['content'])
nbclient.exceptions.CellExecutionError: An error occurred while executing the following cell:
------------------
%%R
Y <- c(2, 3, 3, 4, 3, 2, 0, 3, 8, 11, 6, 6, 7, 12, 11, 11)
N <- c(119, 124, 50, 26, 88, 100, 43, 23, 127, 220, 74, 49, 74, 111, 57, 44)
BP <- factor(rep(1:4, 4))
CHOL <- factor(rep(1:4, rep(4, 4)))
fit.1 <- glm(Y/N ~ 1, weights = N, family = "binomial")
fit.2 <- glm(Y/N ~ CHOL, weights = N, family = "binomial")
fit.3 <- glm(Y/N ~ BP, weights = N, family = "binomial")
fit.4 <- glm(Y/N ~ CHOL + BP, weights = N, family = "binomial")
------------------


UsageError: Cell magic `%%R` not found.

